Workbook

Sheet Dashboard
A1: EBOLA OUTBREAK ANALYSIS | SIERRA LEONE, 2014
A4: Total Cases | C4: Confirmed | E4: Confirmation Rate | G4: Districts | I4: Median Age | K4: Avg Delay (d)
A5: =Metrics!B2 -> 200 | C5: =Metrics!B3 -> 182 | E5: =Metrics!B5 -> 0.91 | G5: =Metrics!B6 -> 6 | I5: =Metrics!B8 -> 32 | K5: =Metrics!B12 -> 5.685
A8: Cases by District | H8: Confirmed vs Suspected
A24: Cases by Age Group | H24: Cases by Sex
A40: Epidemic Curve — Weekly Case Onset

Sheet Data
A1: Case ID | B1: Age | C1: Age Group | D1: Sex | E1: Status | F1: District | G1: Date of Onset | H1: Date of Sample | I1: Reporting Delay (days) | J1: Onset Week
A2: 1 | B2: 20 | C2: 18-29 | D2: Female | E2: Confirmed | F2: Kailahun | G2: 41777 | H2: 41782 | I2: 5 | J2: 41771
A3: 2 | B3: 42 | C3: 30-44 | D3: Female | E3: Confirmed | F3: Kailahun | G3: 41779 | H3: 41784 | I3: 5 | J3: 41778
A4: 5 | B4: 19 | C4: 18-29 | D4: Female | E4: Confirmed | F4: Kailahun | G4: 41780 | H4: 41785 | I4: 5 | J4: 41778
A5: 9 | B5: 54 | C5: 45-59 | D5: Female | E5: Confirmed | F5: Kailahun | G5: 41781 | H5: 41786 | I5: 5 | J5: 41778
A6: 13 | B6: 38 | C6: 30-44 | D6: Female | E6: Confirmed | F6: Kailahun | G6: 41781 | H6: 41786 | I6: 5 | J6: 41778
A7: 14 | B7: 29 | C7: 18-29 | D7: Female | E7: Suspected | F7: Western Urban | G7: 41782 | H7: 41787 | I7: 5 | J7: 41778
A8: 15 | B8: 43 | C8: 30-44 | D8: Female | E8: Suspected | F8: Kailahun | G8: 41783 | H8: 41788 | I8: 5 | J8: 41778
A9: 16 | C9: Unknown | D9: Female | E9: Suspected | F9: Western Urban | G9: 41783 | H9: 41788 | I9: 5 | J9: 41778
A10: 22 | B10: 19 | C10: 18-29 | D10: Male | E10: Suspected | F10: Kailahun | G10: 41785 | H10: 41790 | I10: 5 | J10: 41785
A11: 20 | B11: 3 | C11: 0-4 | D11: Female | E11: Suspected | F11: Kailahun | G11: 41785 | H11: 41790 | I11: 5 | J11: 41785
A12: 19 | B12: 35 | C12: 30-44 | D12: Female | E12: Suspected | F12: Kailahun | G12: 41785 | H12: 41790 | I12: 5 | J12: 41785
A13: 26 | B13: 26 | C13: 18-29 | D13: Female | E13: Suspected | F13: Western Urban | G13: 41785 | H13: 41790 | I13: 5 | J13: 41785
A14: 25 | B14: 62 | C14: 60+ | D14: Male | E14: Suspected | F14: Western Urban | G14: 41785 | H14: 41790 | I14: 5 | J14: 41785
A15: 24 | B15: 2 | C15: 0-4 | D15: Male | E15: Suspected | F15: Bo | G15: 41785 | H15: 41790 | I15: 5 | J15: 41785
A16: 23 | B16: 3 | C16: 0-4 | D16: Female | E16: Suspected | F16: Bo | G16: 41785 | H16: 41790 | I16: 5 | J16: 41785
A17: 17 | B17: 38 | C17: 30-44 | D17: Female | E17: Confirmed | F17: Kailahun | G17: 41785 | H17: 41790 | I17: 5 | J17: 41785
A18: 29 | B18: 68 | C18: 60+ | D18: Female | E18: Confirmed | F18: Kailahun | G18: 41786 | H18: 41791 | I18: 5 | J18: 41785
A19: 31 | B19: 2 | C19: 0-4 | D19: Female | E19: Suspected | F19: Kailahun | G19: 41786 | H19: 41791 | I19: 5 | J19: 41785
A20: 34 | B20: 16 | C20: 5-17 | D20: Female | E20: Suspected | F20: Kailahun | G20: 41786 | H20: 41791 | I20: 5 | J20: 41785
A21: 27 | B21: 43 | C21: 30-44 | D21: Male | E21: Confirmed | F21: Kailahun | G21: 41786 | H21: 41791 | I21: 5 | J21: 41785
... A24: 30 | B24: 45 | C24: 45-59 | D24: Female | E24: Suspected | F24: Kenema | G24: 41786 | H24: 41790 | I24: 4 | J24: 41785
A25: 36 | C25: Unknown | D25: Male | E25: Suspected | F25: Kailahun | G25: 41787 | H25: 41792 | I25: 5 | J25: 41785
A26: 37 | B26: 25 | C26: 18-29 | D26: Female | E26: Confirmed | F26: Kailahun | G26: 41788 | H26: 41793 | I26: 5 | J26: 41785
A27: 43 | B27: 37 | C27: 30-44 | D27: Male | E27: Confirmed | F27: Kailahun | G27: 41788 | H27: 41793 | I27: 5 | J27: 41785
A28: 48 | B28: 28 | C28: 18-29 | D28: Female | E28: Suspected | F28: Kailahun | G28: 41788 | H28: 41793 | I28: 5 | J28: 41785
A29: 45 | B29: 41 | C29: 30-44 | D29: Male | E29: Suspected | F29: Kailahun | G29: 41788 | H29: 41793 | I29: 5 | J29: 41785
A30: 40 | B30: 20 | C30: 18-29 | D30: Female | E30: Confirmed | F30: Kailahun | G30: 41788 | H30: 41793 | I30: 5 | J30: 41785
A31: 42 | B31: 45 | C31: 45-59 | D31: Female | E31: Confirmed | F31: Kailahun | G31: 41788 | H31: 41793 | I31: 5 | J31: 41785
A32: 44 | B32: 35 | C32: 30-44 | D32: Female | E32: Suspected | F32: Kailahun | G32: 41788 | H32: 41793 | I32: 5 | J32: 41785
A33: 39 | B33: 65 | C33: 60+ | D33: Female | E33: Confirmed | F33: Kailahun | G33: 41788 | H33: 41793 | I33: 5 | J33: 41785
A34: 41 | B34: 22 | C34: 18-29 | D34: Female | E34: Confirmed | F34: Kailahun | G34: 41788 | H34: 41793 | I34: 5 | J34: 41785
A35: 50 | B35: 11 | C35: 5-17 | D35: Female | E35: Confirmed | F35: Kailahun | G35: 41789 | H35: 41794 | I35: 5 | J35: 41785
A36: 49 | B36: 44 | C36: 30-44 | D36: Male | E36: Confirmed | F36: Kailahun | G36: 41789 | H36: 41794 | I36: 5 | J36: 41785
A37: 53 | B37: 30 | C37: 30-44 | D37: Female | E37: Confirmed | F37: Kailahun | G37: 41789 | H37: 41794 | I37: 5 | J37: 41785
A38: 51 | B38: 46 | C38: 45-59 | D38: Female | E38: Confirmed | F38: Kailahun | G38: 41789 | H38: 41794 | I38: 5 | J38: 41785
A39: 56 | C39: Unknown | D39: Female | E39: Confirmed | F39: Kailahun | G39: 41790 | H39: 41795 | I39: 5 | J39: 41785
A40: 57 | B40: 30 | C40: 30-44 | D40: Female | E40: Confirmed | F40: Port Loko | G40: 41790 | H40: 41797 | I40: 7 | J40: 41785
A41: 61 | B41: 7 | C41: 5-17 | D41: Female | E41: Confirmed | F41: Kailahun | G41: 41791 | H41: 41796 | I41: 5 | J41: 41785
A42: 60 | B42: 17 | C42: 5-17 | D42: Female | E42: Confirmed | F42: Kailahun | G42: 41791 | H42: 41796 | I42: 5 | J42: 41785
...

Sheet Metrics
A1: KEY METRICS — Ebola Outbreak, Sierra Leone (2014) | H1: Confirmed | I1: =Metrics!B3 -> 182
A2: Total Cases | B2: =COUNTA(Data!E2:E201) -> 200 | H2: Suspected | I2: =Metrics!B4 -> 18
A3: Confirmed Cases | B3: =COUNTIF(Data!$E$2:$E$201,"Confirmed") -> 182
A4: Suspected Cases | B4: =COUNTIF(Data!$E$2:$E$201,"Suspected") -> 18
A5: Confirmation Rate | B5: =COUNTIF(Data!$E$2:$E$201,"Confirmed")/COUNTA(Data!E2:E201) -> 0.91
A6: Districts Affected | B6: =SUMPRODUCT(1/COUNTIF(Data!F2:F201,Data!F2:F201)) -> 6
A7: Mean Age (yrs) | B7: =AVERAGE(Data!$B$2:$B$201) -> 33.124352
A8: Median Age (yrs) | B8: =MEDIAN(Data!$B$2:$B$201) -> 32
A9: Female Cases | B9: =COUNTIF(Data!$D$2:$D$201,"Female") -> 124
A10: Male Cases | B10: =COUNTIF(Data!$D$2:$D$201,"Male") -> 76
A11: Female : Male Ratio | B11: =COUNTIF(Data!$D$2:$D$201,"Female")/COUNTIF(Data!$D$2:$D$201,"Male") -> 1.6315789
A12: Avg Reporting Delay (days) | B12: =AVERAGE(Data!$I$2:$I$201) -> 5.685
A13: Max Reporting Delay (days) | B13: =MAX(Data!$I$2:$I$201) -> 45
A14: Outbreak Start (onset) | B14: =TEXT(MIN(Data!G2:G201),"yyyy-mm-dd") -> 2014-05-18
A15: Outbreak End (onset) | B15: =TEXT(MAX(Data!G2:G201),"yyyy-mm-dd") -> 2014-06-29
A16: Outbreak Duration (days) | B16: =MAX(Data!G2:G201)-MIN(Data!G2:G201) -> 42
A18: Cases by District
A19: District | B19: Total | C19: Confirmed | D19: Suspected | E19: % of Total
A20: Bo | B20: =COUNTIF(Data!$F$2:$F$201,"Bo") -> 4 | C20: =COUNTIFS(Data!$F$2:$F$201,"Bo",Data!$E$2:$E$201,"Confirmed") -> 2 | D20: =COUNTIFS(Data!$F$2:$F$201,"Bo",Data!$E$2:$E$201,"Suspected") -> 2 | E20: =B20/SUM($B$20:$B$25) -> 0.02
A21: Kailahun | B21: =COUNTIF(Data!$F$2:$F$201,"Kailahun") -> 146 | C21: =COUNTIFS(Data!$F$2:$F$201,"Kailahun",Data!$E$2:$E$201,"Confirmed") -> 135 | D21: =COUNTIFS(Data!$F$2:$F$201,"Kailahun",Data!$E$2:$E$201,"Suspected") -> 11 | E21: =B21/SUM($B$20:$B$25) -> 0.73
A22: Kenema | B22: =COUNTIF(Data!$F$2:$F$201,"Kenema") -> 41 | C22: =COUNTIFS(Data!$F$2:$F$201,"Kenema",Data!$E$2:$E$201,"Confirmed") -> 40 | D22: =COUNTIFS(Data!$F$2:$F$201,"Kenema",Data!$E$2:$E$201,"Suspected") -> 1 | E22: =B22/SUM($B$20:$B$25) -> 0.205
A23: Kono | B23: =COUNTIF(Data!$F$2:$F$201,"Kono") -> 2 | C23: =COUNTIFS(Data!$F$2:$F$201,"Kono",Data!$E$2:$E$201,"Confirmed") -> 2 | D23: =COUNTIFS(Data!$F$2:$F$201,"Kono",Data!$E$2:$E$201,"Suspected") -> 0 | E23: =B23/SUM($B$20:$B$25) -> 0.01
A24: Port Loko | B24: =COUNTIF(Data!$F$2:$F$201,"Port Loko") -> 2 | C24: =COUNTIFS(Data!$F$2:$F$201,"Port Loko",Data!$E$2:$E$201,"Confirmed") -> 2 | D24: =COUNTIFS(Data!$F$2:$F$201,"Port Loko",Data!$E$2:$E$201,"Suspected") -> 0 | E24: =B24/SUM($B$20:$B$25) -> 0.01
A25: Western Urban | B25: =COUNTIF(Data!$F$2:$F$201,"Western Urban") -> 5 | C25: =COUNTIFS(Data!$F$2:$F$201,"Western Urban",Data!$E$2:$E$201,"Confirmed") -> 1 | D25: =COUNTIFS(Data!$F$2:$F$201,"Western Urban",Data!$E$2:$E$201,"Suspected") -> 4 | E25: =B25/SUM($B$20:$B$25) -> 0.025
A27: Cases by Age Group
A28: Age Group | B28: Cases
A29: 0-4 | B29: =COUNTIF(Data!$C$2:$C$201,"0-4") -> 11
A30: 5-17 | B30: =COUNTIF(Data!$C$2:$C$201,"5-17") -> 32
A31: 18-29 | B31: =COUNTIF(Data!$C$2:$C$201,"18-29") -> 33
A32: 30-44 | B32: =COUNTIF(Data!$C$2:$C$201,"30-44") -> 66
A33: 45-59 | B33: =COUNTIF(Data!$C$2:$C$201,"45-59") -> 30
A34: 60+ | B34: =COUNTIF(Data!$C$2:$C$201,"60+") -> 21
A36: Cases by Sex
A37: Sex | B37: Cases
A38: Female | B38: =COUNTIF(Data!$D$2:$D$201,"Female") -> 124
A39: Male | B39: =COUNTIF(Data!$D$2:$D$201,"Male") -> 76
A41: Epidemic Curve (Weekly Onset)
A42: Week Starting | B42: New Cases
A43: 41771 | B43: =COUNTIF(Data!$J$2:$J$201,DATE(2014,5,12)) -> 1
A44: 41778 | B44: =COUNTIF(Data!$J$2:$J$201,DATE(2014,5,19)) -> 7
...
